Workbook

Sheet Historias de Usuario
B1: Desarrollo ágil: Historias de usuario y criterios de aceptación
B2: Proyecto CuidaTrack · Product Backlog v2 · 1 de octubre de 2026
C4: Enunciado de la historia | G4: Criterios de aceptación | K4: Planificación | P4: Detalle técnico
B5: Identificador (ID) de la historia | C5: Rol | D5: Característica / Funcionalidad | E5: Razón / Resultado | F5: Número (#) de escenario | G5: Criterio de aceptación (Título) | H5: Contexto | I5: Evento | J5: Resultado / Comportamiento esperado | K5: Épica | L5: Prioridad (MoSCoW) | M5: Puntos | N5: Responsable de desarrollo | O5: Tipo / estado | P5: Criterios técnicos
B6: HU-01 | C6: Como cuidador/a | D6: Necesito crear mi cuenta solo con mi correo y una contraseña | E6: Con la finalidad de empezar a usar la app en pocos minutos. | F6: 1 | G6: Registro exitoso | H6: En caso que el correo no tiene una cuenta en la app | I6: Cuando completo correo y contraseña en la pantalla de registro y confirmo | J6: El sistema crea mi cuenta y me lleva a la pantalla de inicio. | K6: E1 | L6: Must | M6: 3 | N6: Bastián Ñiripil | O6: En backlog | P6: Correo único. Contraseña de al menos 8 caracteres guardada con hash (bcrypt o argon2), nunca en texto plano.
F7: 2 | G7: Correo ya registrado | H7: En caso que el correo ya tiene una cuenta | I7: Cuando intento registrarme con ese correo | J7: El sistema me avisa que el correo ya está en uso y me ofrece recuperar la clave.
F8: 3 | G8: Contraseña muy corta | H8: En caso que la contraseña tiene menos de 8 caracteres | I8: Cuando intento crear la cuenta | J8: El sistema me explica que la contraseña es muy corta y no crea la cuenta.
B10: HU-02 | C10: Como cuidador/a | D10: Necesito entrar a la app desde mi celular sin escribir la clave cada vez, y recuperarla si la olvido | E10: Con la finalidad de anotar en el momento sin trabas. | F10: 1 | G10: Sesión recordada | H10: En caso que ya inicié sesión antes en mi celular | I10: Cuando abro la app | J10: El sistema me lleva directo a la pantalla de inicio sin pedir la clave. | K10: E1 | L10: Must | M10: 5 | N10: Bastián Ñiripil | O10: En backlog | P10: Token con expiración (duración por definir: pregunta abierta). Cerrar sesión invalida el token. Mensaje de error genérico. Enlace de recuperación de un solo uso y con vencimiento.
F11: 2 | G11: Datos incorrectos | H11: En caso que escribo mal mi correo o mi clave | I11: Cuando intento entrar | J11: El sistema muestra un mensaje claro de datos incorrectos, sin indicar cuál de los dos está mal.
F12: 3 | G12: Recuperar la clave | H12: En caso que olvidé mi clave | I12: Cuando pido recuperarla con mi correo | J12: El sistema me envía un correo con un enlace para crear una clave nueva.
F13: 4 | G13: Cerrar sesión | H13: En caso que tengo la sesión abierta | I13: Cuando elijo "Cerrar sesión" en el menú | J13: El sistema cierra la sesión y la próxima vez me pide la clave.
B15: HU-03 | C15: Como cuidador/a principal | D15: Necesito entender en palabras simples qué se hace con los datos de salud de mi familiar antes de ingresarlos | E15: Con la finalidad de decidir con confianza si los anoto en la app. | F15: 1 | G15: Primera vez | H15: En caso que todavía no agrego a mi familiar | I15: Cuando voy a registrarlo/a | J15: El sistema me muestra un texto breve, sin lenguaje legal, que dice qué se guarda, quién lo ve y cómo borrarlo. | K15: E1 | L15: Must | M15: 3 | N15: Bastián Ñiripil | O15: En backlog | P15: Se guardan la fecha, la versión del texto aceptado y la fecha de revocación. Consentimiento expreso para datos de salud, como exige la Ley 21.719 (vigente desde el 1 de diciembre de 2026). El texto debe declarar que se guardan las consultas al asistente (HU-30). Pregunta abierta: los datos son de la persona mayor; definir si el cuidador declara contar con su autorización o ser su representante.
F16: 2 | G16: No acepto el texto | H16: En caso que estoy leyendo el texto | I16: Cuando no lo acepto | J16: El sistema no me deja agregar a mi familiar y me explica por qué.
F17: 3 | G17: Revisar o retirar la aceptación | H17: En caso que ya acepté el texto antes | I17: Cuando entro a la configuración | J17: El sistema me deja volver a leer el texto y retirar mi aceptación.
B19: HU-04 | C19: Como cuidador/a principal | D19: Necesito poder borrar mi cuenta y toda la información de mi familiar cuando deje de cuidarlo/a | E19: Con la finalidad de que esos datos no queden guardados en ninguna parte. | F19: 1 | G19: Pedir el borrado | H19: En caso que quiero dejar de usar la app | I19: Cuando elijo "Borrar mi cuenta" en la configuración | J19: El sistema me explica qué se va a borrar y me pide confirmar dos veces. | K19: E1 | L19: Should | M19: 3 | N19: Bastián Ñiripil | O19: En backlog | P19: Se eliminan o anonimizan todos los registros asociados. Pregunta abierta: qué pasa con el acceso de los cuidadores secundarios cuando el principal borra su cuenta.
F20: 2 | G20: Borrado terminado | H20: En caso que confirmé el borrado | I20: Cuando el proceso termina | J20: El sistema me envía un correo confirmando que la información fue eliminada.
B22: HU-05 | C22: Como cuidador/a principal | D22: Necesito agregar a mi familiar con unos pocos datos (nombre, edad y cuánta ayuda necesita) | E22: Con la finalidad de tener en un solo lugar todo lo de su cuidado. | F22: 1 | G22: Agregar a mi familiar | H22: En caso que acepté el texto sobre el uso de los datos | I22: Cuando completo nombre, fecha de nacimiento y cuánta ayuda necesita | J22: El sistema guarda a mi familiar y lo muestra en la pantalla de inicio. | K22: E2 | L22: Must | M22: 2 | N22: Bastián Ñiripil | O22: En backlog | P22: "Cuánta ayuda necesita" se guarda como lista cerrada (leve, moderada, severa).
F23: 2 | G23: Fecha imposible | H23: En caso que escribo una fecha de nacimiento futura | I23: Cuando intento guardar | J23: El sistema me pide corregir la fecha.
F24: 3 | G24: Elegir cuánta ayuda necesita | H24: En caso que no sé qué opción elegir | I24: Cuando reviso las opciones | J24: El sistema describe cada opción en palabras simples.
B26: HU-06 | C26: Como cuidador/a principal | D26: Necesito invitar a los familiares que me ayudan | E26: Con la finalidad de que ellos también anoten lo que hacen y no tener que estar avisando todo por mensaje. | F26: 1 | G26: Invitar a un familiar | H26: En caso que tengo a mi familiar registrado | I26: Cuando invito a otra persona con su correo | J26: El sistema le envía la invitación y la muestra como pendiente en mi equipo de cuidado. | K26: E2 | L26: Must | M26: 5 | N26: Bastián Ñiripil | O26: En backlog | P26: Invitación por correo con enlace de un solo uso. Relación N:M entre cuidador y persona mayor (ASIGNACION_CUIDADO) con rol principal o secundario.
F27: 2 | G27: Aceptar la invitación | H27: En caso que un familiar recibió la invitación | I27: Cuando la acepta | J27: El sistema le da acceso solo a la persona mayor que le compartí.
F28: 3 | G28: Quitar el acceso | H28: En caso que un familiar ya no ayuda en el cuidado | I28: Cuando le quito el acceso desde mi equipo de cuidado | J28: El sistema deja de mostrarle a mi familiar de inmediato.
B30: HU-07 | C30: Como cuidador/a principal | D30: Necesito estar seguro/a de que solo las personas que yo invité pueden ver la información de mi familiar | E30: Con la finalidad de confiarle a la app datos tan personales. | F30: 1 | G30: Ver quién tiene acceso | H30: En caso que invité a uno o más familiares | I30: Cuando entro a "Equipo de cuidado" | J30: El sistema me muestra exactamente quiénes tienen acceso. | K30: E2 | L30: Must | M30: 3 | N30: Bastián Ñiripil | O30: En backlog | P30: Toda consulta a la API filtra por asignación. Pedir un recurso ajeno responde 403, verificado con una prueba automatizada.
F31: 2 | G31: Intento sin invitación | H31: En caso que alguien sin invitación tiene un enlace a la información de mi familiar | I31: Cuando intenta abrirlo | J31: El sistema no le muestra la información.
B33: HU-38 | C33: Como cuidador/a que termina su turno | D33: Necesito dejar una nota rápida de cómo quedó mi familiar y qué falta | E33: Con la finalidad de que quien me reemplaza no parta de cero. | F33: 1 | G33: Dejar la nota | H33: En caso que estoy terminando mi turno | I33: Cuando escribo una nota corta y la guardo | J33: El sistema la guarda con mi nombre y la hora. | K33: E2 | L33: Should | M33: 3 | N33: Bastián Ñiripil | O33: Propuesta nueva | P33: La nota queda asociada a la persona mayor, a su autor y a la fecha.
F34: 2 | G34: Leer la nota | H34: En caso que otro familiar dejó una nota de turno | I34: Cuando abro la app al empezar mi turno | J34: El sistema me muestra la nota apenas entro.
B36: HU-08 | C36: Como cuidador/a | D36: Necesito anotar los remedios de mi familiar tal como vienen en la receta (cuál, cuánto y a qué horas) | E36: Con la finalidad de no tener que acordarme de todos los horarios. | F36: 1 | G36: Remedio con varias horas | H36: En caso que la receta indica un remedio varias veces al día | I36: Cuando lo anoto con su cantidad y sus horas (por ejemplo, 08:00, 14:00 y 20:00) | J36: El sistema lo agrega de inmediato a la lista del día, una vez por cada hora. | K36: E3 | L36: Must | M36: 5 | N36: Bastián Ñiripil | O36: En backlog | P36: Varios horarios por tratamiento. Fecha de término opcional.
F37: 2 | G37: Remedio permanente | H37: En caso que el remedio no tiene fecha de término | I37: Cuando lo guardo sin fecha de término | J37: El sistema lo sigue mostrando todos los días hasta que yo lo suspenda.
F38: 3 | G38: Remedio con fecha de término | H38: En caso que el remedio tiene fecha de término | I38: Cuando pasa esa fecha | J38: El sistema deja de mostrarlo en la lista del día.
B40: HU-09 | C40: Como cuidador/a | D40: Necesito ver apenas abro la app qué remedios tocan hoy y cuáles ya se dieron | E40: Con la finalidad de saber en segundos qué falta. | F40: 1 | G40: Lista del día | H40: En caso que mi familiar tiene remedios para hoy | I40: Cuando abro la app | J40: El sistema me muestra los remedios del día ordenados por hora. | K40: E3 | L40: Must | M40: 3 | N40: Bastián Ñiripil | O40: En backlog | P40: —
F41: 2 | G41: Estados visibles | H41: En caso que hay remedios pendientes, dados y atrasados | I41: Cuando reviso la lista | J41: El sistema distingue cada estado con texto e ícono, no solo con color.
B43: HU-10 | C43: Como cuidador/a | D43: Necesito marcar un remedio como dado con un solo toque, aunque tenga una mano ocupada | E43: Con la finalidad de anotar sin dejar lo que estoy haciendo. | F43: 1 | G43: Marcar como dado | H43: En caso que hay un remedio pendiente en la pantalla de inicio | I43: Cuando toco el botón "Dado" | J43: El sistema lo marca como dado con la hora actual. | K43: E3 | L43: Must | M43: 3 | N43: Bastián Ñiripil | O43: En backlog | P43: Se completa en máximo 2 interacciones desde la pantalla de inicio. Área táctil del botón de al menos 48 × 48 dp, alcanzable con el pulgar.
F44: 2 | G44: Cambiar la hora | H44: En caso que lo di antes y lo estoy anotando después | I44: Cuando cambio la hora del registro | J44: El sistema guarda la hora que indiqué.
F45: 3 | G45: Deshacer | H45: En caso que lo marqué por error | I45: Cuando toco "Deshacer" justo después | J45: El sistema vuelve el remedio a pendiente.
B47: HU-11 | C47: Como cuidador/a | D47: Necesito que la app me muestre si un remedio se dio bastante antes o después de su hora | E47: Con la finalidad de saber cuándo conviene preguntarle al médico o en la farmacia. | F47: 1 | G47: Dado a la hora | H47: En caso que el remedio se marca dentro del margen de su hora | I47: Cuando lo marco como dado | J47: El sistema lo muestra como dado a la hora. | K47: E3 | L47: Must | M47: 3 | N47: Bastián Ñiripil | O47: En backlog | P47: Margen configurable, con propuesta de ±30 minutos. Pregunta abierta: margen de la ventana horaria. El resultado (dentro o fuera de la ventana) se guarda en el registro.
F48: 2 | G48: Dado fuera de hora | H48: En caso que el remedio se marca fuera del margen de su hora | I48: Cuando lo marco como dado | J48: El sistema muestra un mensaje neutro, sin culpa (por ejemplo, "anotado 1 hora después de lo indicado"), y no indica qué hacer con la dosis siguiente.
B50: HU-37 | C50: Como cuidador/a | D50: Necesito que el celular me avise cuando toca un remedio y poder marcarlo como dado desde el mismo aviso | E50: Con la finalidad de no depender de mi memoria en los días pesados. | F50: 1 | G50: Aviso a la hora | H50: En caso que un remedio está programado para una hora | I50: Cuando llega esa hora | J50: El sistema me envía un aviso al celular con el nombre y la cantidad del remedio. | K50: E3 | L50: Must | M50: 5 | N50: Luis Pérez | O50: Propuesta nueva | P50: Notificaciones push. En una app web, el iPhone solo las recibe si la app está instalada en la pantalla de inicio. Pregunta abierta: validar factibilidad antes de comprometer la historia.
F51: 2 | G51: Marcar desde el aviso | H51: En caso que recibí el aviso | I51: Cuando toco "Dado" en el aviso | J51: El sistema lo registra como dado sin que tenga que abrir la app.
B53: HU-12 | C53: Como cuidador/a | D53: Necesito anotar rápido cuando mi familiar no se tomó un remedio y por qué | E53: Con la finalidad de tener esa información a mano en el próximo control. | F53: 1 | G53: Remedio no dado | H53: En caso que mi familiar no se tomó un remedio | I53: Cuando marco "No se dio" y elijo un motivo (lo rechazó, se acabó, indicación médica, otro) | J53: El sistema lo guarda como no dado, con su motivo. | K53: E3 | L53: Should | M53: 2 | N53: Bastián Ñiripil | O53: En backlog | P53: Estado de la toma (administrada u omitida) y motivo de una lista cerrada.
F54: 2 | G54: Nota opcional | H54: En caso que elegí un motivo | I54: Cuando agrego una nota | J54: El sistema la guarda junto al registro.
...

Sheet Épicas
B1: Épicas del Product Backlog
B2: Proyecto CuidaTrack · Product Backlog v2 · 1 de octubre de 2026. Los totales se calculan desde la pestaña Historias de Usuario.
B4: ID épica | C4: Épica | D4: Qué resuelve para la persona cuidadora | E4: Objetivos Fase 1 | F4: Responsable de desarrollo | G4: Backlog MVP | K4: Propuestas v2
G5: Historias | H5: N° historias | I5: Puntos | J5: Puntos Must | K5: Historias nuevas | L5: Puntos
B6: E1 | C6: Cuenta y acceso | D6: Entrar fácil a la app desde el celular y decidir con confianza qué datos de su familiar entrega. | E6: OE4 | F6: Bastián Ñiripil | G6: HU-01, HU-02, HU-03, HU-04 | H6: =COUNTIFS('Historias de Usuario'!$K$6:$K$128,$B6,'Historias de Usuario'!$O$6:$O$128,"<>Propuesta nueva") -> 4 | I6: =SUMIFS('Historias de Usuario'!$M$6:$M$128,'Historias de Usuario'!$K$6:$K$128,$B6,'Historias de Usuario'!$O$6:$O$128,"<>Propuesta nueva") -> 14 | J6: =SUMIFS('Historias de Usuario'!$M$6:$M$128,'Historias de Usuario'!$K$6:$K$128,$B6,'Historias de Usuario'!$O$6:$O$128,"<>Propuesta nueva",'Historias de Usuario'!$L$6:$L$128,"Must") -> 11 | K6: — | L6: =SUMIFS('Historias de Usuario'!$M$6:$M$128,'Historias de Usuario'!$K$6:$K$128,$B6,'Historias de Usuario'!$O$6:$O$128,"Propuesta nueva") -> 0
B7: E2 | C7: Persona mayor y equipo de cuidado | D7: Registrar a la persona mayor y compartir su cuidado con la familia, controlando quién ve la información. | E7: OE1, OE4 | F7: Bastián Ñiripil | G7: HU-05, HU-06, HU-07 | H7: =COUNTIFS('Historias de Usuario'!$K$6:$K$128,$B7,'Historias de Usuario'!$O$6:$O$128,"<>Propuesta nueva") -> 3 | I7: =SUMIFS('Historias de Usuario'!$M$6:$M$128,'Historias de Usuario'!$K$6:$K$128,$B7,'Historias de Usuario'!$O$6:$O$128,"<>Propuesta nueva") -> 10 | J7: =SUMIFS('Historias de Usuario'!$M$6:$M$128,'Historias de Usuario'!$K$6:$K$128,$B7,'Historias de Usuario'!$O$6:$O$128,"<>Propuesta nueva",'Historias de Usuario'!$L$6:$L$128,"Must") -> 10 | K7: HU-38 | L7: =SUMIFS('Historias de Usuario'!$M$6:$M$128,'Historias de Usuario'!$K$6:$K$128,$B7,'Historias de Usuario'!$O$6:$O$128,"Propuesta nueva") -> 3
B8: E3 | C8: Medicamentos | D8: Saber qué remedio toca, anotarlo en un toque y evitar olvidos o errores de horario. | E8: OE1 | F8: Bastián Ñiripil (HU-37 propuesta: Luis Pérez) | G8: HU-08, HU-09, HU-10, HU-11, HU-12, HU-13 | H8: =COUNTIFS('Historias de Usuario'!$K$6:$K$128,$B8,'Historias de Usuario'!$O$6:$O$128,"<>Propuesta nueva") -> 6 | I8: =SUMIFS('Historias de Usuario'!$M$6:$M$128,'Historias de Usuario'!$K$6:$K$128,$B8,'Historias de Usuario'!$O$6:$O$128,"<>Propuesta nueva") -> 19 | J8: =SUMIFS('Historias de Usuario'!$M$6:$M$128,'Historias de Usuario'!$K$6:$K$128,$B8,'Historias de Usuario'!$O$6:$O$128,"<>Propuesta nueva",'Historias de Usuario'!$L$6:$L$128,"Must") -> 14 | K8: HU-37, HU-41 | L8: =SUMIFS('Historias de Usuario'!$M$6:$M$128,'Historias de Usuario'!$K$6:$K$128,$B8,'Historias de Usuario'!$O$6:$O$128,"Propuesta nueva") -> 10
B9: E4 | C9: Actividades y tiempo de cuidado | D9: Dejar registro de los cuidados diarios para que la familia sepa qué se hizo. | E9: OE1 | F9: Bastián Ñiripil | G9: HU-14, HU-15, HU-16 | H9: =COUNTIFS('Historias de Usuario'!$K$6:$K$128,$B9,'Historias de Usuario'!$O$6:$O$128,"<>Propuesta nueva") -> 3 | I9: =SUMIFS('Historias de Usuario'!$M$6:$M$128,'Historias de Usuario'!$K$6:$K$128,$B9,'Historias de Usuario'!$O$6:$O$128,"<>Propuesta nueva") -> 8 | J9: =SUMIFS('Historias de Usuario'!$M$6:$M$128,'Historias de Usuario'!$K$6:$K$128,$B9,'Historias de Usuario'!$O$6:$O$128,"<>Propuesta nueva",'Historias de Usuario'!$L$6:$L$128,"Must") -> 3 | K9: — | L9: =SUMIFS('Historias de Usuario'!$M$6:$M$128,'Historias de Usuario'!$K$6:$K$128,$B9,'Historias de Usuario'!$O$6:$O$128,"Propuesta nueva") -> 0
B10: E5 | C10: Citas médicas | D10: No perder horas médicas y guardar lo que dijo el médico. | E10: OE1 | F10: Bastián Ñiripil (HU-19: Luis Pérez) | G10: HU-17, HU-18, HU-19 | H10: =COUNTIFS('Historias de Usuario'!$K$6:$K$128,$B10,'Historias de Usuario'!$O$6:$O$128,"<>Propuesta nueva") -> 3 | I10: =SUMIFS('Historias de Usuario'!$M$6:$M$128,'Historias de Usuario'!$K$6:$K$128,$B10,'Historias de Usuario'!$O$6:$O$128,"<>Propuesta nueva") -> 7 | J10: =SUMIFS('Historias de Usuario'!$M$6:$M$128,'Historias de Usuario'!$K$6:$K$128,$B10,'Historias de Usuario'!$O$6:$O$128,"<>Propuesta nueva",'Historias de Usuario'!$L$6:$L$128,"Must") -> 2 | K10: — | L10: =SUMIFS('Historias de Usuario'!$M$6:$M$128,'Historias de Usuario'!$K$6:$K$128,$B10,'Historias de Usuario'!$O$6:$O$128,"Propuesta nueva") -> 0
B11: E6 | C11: Sobrecarga del cuidador | D11: Darse cuenta a tiempo del propio cansancio y decidir cuándo pedir ayuda. | E11: OE1, OG | F11: Bastián Ñiripil (HU-20) / Luis Pérez (HU-21) | G11: HU-20, HU-21 | H11: =COUNTIFS('Historias de Usuario'!$K$6:$K$128,$B11,'Historias de Usuario'!$O$6:$O$128,"<>Propuesta nueva") -> 2 | I11: =SUMIFS('Historias de Usuario'!$M$6:$M$128,'Historias de Usuario'!$K$6:$K$128,$B11,'Historias de Usuario'!$O$6:$O$128,"<>Propuesta nueva") -> 6 | J11: =SUMIFS('Historias de Usuario'!$M$6:$M$128,'Historias de Usuario'!$K$6:$K$128,$B11,'Historias de Usuario'!$O$6:$O$128,"<>Propuesta nueva",'Historias de Usuario'!$L$6:$L$128,"Must") -> 6 | K11: — | L11: =SUMIFS('Historias de Usuario'!$M$6:$M$128,'Historias de Usuario'!$K$6:$K$128,$B11,'Historias de Usuario'!$O$6:$O$128,"Propuesta nueva") -> 0
B12: E7 | C12: Reportería | D12: Ver de un vistazo cómo va el cuidado y llevar un resumen al control médico. | E12: OG | F12: Luis Pérez | G12: HU-22, HU-23, HU-24 | H12: =COUNTIFS('Historias de Usuario'!$K$6:$K$128,$B12,'Historias de Usuario'!$O$6:$O$128,"<>Propuesta nueva") -> 3 | I12: =SUMIFS('Historias de Usuario'!$M$6:$M$128,'Historias de Usuario'!$K$6:$K$128,$B12,'Historias de Usuario'!$O$6:$O$128,"<>Propuesta nueva") -> 13 | J12: =SUMIFS('Historias de Usuario'!$M$6:$M$128,'Historias de Usuario'!$K$6:$K$128,$B12,'Historias de Usuario'!$O$6:$O$128,"<>Propuesta nueva",'Historias de Usuario'!$L$6:$L$128,"Must") -> 5 | K12: HU-40 | L12: =SUMIFS('Historias de Usuario'!$M$6:$M$128,'Historias de Usuario'!$K$6:$K$128,$B12,'Historias de Usuario'!$O$6:$O$128,"Propuesta nueva") -> 3
B13: E8 | C13: Alertas tempranas | D13: Recibir avisos a tiempo cuando algo se escapa, incluido el propio agotamiento. | E13: OE3 | F13: Luis Pérez | G13: HU-25, HU-26, HU-28, HU-27 | H13: =COUNTIFS('Historias de Usuario'!$K$6:$K$128,$B13,'Historias de Usuario'!$O$6:$O$128,"<>Propuesta nueva") -> 4 | I13: =SUMIFS('Historias de Usuario'!$M$6:$M$128,'Historias de Usuario'!$K$6:$K$128,$B13,'Historias de Usuario'!$O$6:$O$128,"<>Propuesta nueva") -> 13 | J13: =SUMIFS('Historias de Usuario'!$M$6:$M$128,'Historias de Usuario'!$K$6:$K$128,$B13,'Historias de Usuario'!$O$6:$O$128,"<>Propuesta nueva",'Historias de Usuario'!$L$6:$L$128,"Must") -> 10 | K13: HU-39 | L13: =SUMIFS('Historias de Usuario'!$M$6:$M$128,'Historias de Usuario'!$K$6:$K$128,$B13,'Historias de Usuario'!$O$6:$O$128,"Propuesta nueva") -> 3
B14: E9 | C14: Asistente IA | D14: Entender la semana en lenguaje simple y resolver dudas sobre lo anotado, sin consejos médicos. | E14: OE2 | F14: Luis Pérez | G14: HU-29, HU-31, HU-30 | H14: =COUNTIFS('Historias de Usuario'!$K$6:$K$128,$B14,'Historias de Usuario'!$O$6:$O$128,"<>Propuesta nueva") -> 3 | I14: =SUMIFS('Historias de Usuario'!$M$6:$M$128,'Historias de Usuario'!$K$6:$K$128,$B14,'Historias de Usuario'!$O$6:$O$128,"<>Propuesta nueva") -> 19 | J14: =SUMIFS('Historias de Usuario'!$M$6:$M$128,'Historias de Usuario'!$K$6:$K$128,$B14,'Historias de Usuario'!$O$6:$O$128,"<>Propuesta nueva",'Historias de Usuario'!$L$6:$L$128,"Must") -> 11 | K14: — | L14: =SUMIFS('Historias de Usuario'!$M$6:$M$128,'Historias de Usuario'!$K$6:$K$128,$B14,'Historias de Usuario'!$O$6:$O$128,"Propuesta nueva") -> 0
B15: E10 | C15: Seguridad y despliegue | D15: Confiar en que la información de su familiar está protegida. Incluye la historia habilitadora de despliegue. | E15: OE4 | F15: Bastián Ñiripil | G15: HU-32, HU-33, HU-34 | H15: =COUNTIFS('Historias de Usuario'!$K$6:$K$128,$B15,'Historias de Usuario'!$O$6:$O$128,"<>Propuesta nueva") -> 3 | I15: =SUMIFS('Historias de Usuario'!$M$6:$M$128,'Historias de Usuario'!$K$6:$K$128,$B15,'Historias de Usuario'!$O$6:$O$128,"<>Propuesta nueva") -> 13 | J15: =SUMIFS('Historias de Usuario'!$M$6:$M$128,'Historias de Usuario'!$K$6:$K$128,$B15,'Historias de Usuario'!$O$6:$O$128,"<>Propuesta nueva",'Historias de Usuario'!$L$6:$L$128,"Must") -> 10 | K15: — | L15: =SUMIFS('Historias de Usuario'!$M$6:$M$128,'Historias de Usuario'!$K$6:$K$128,$B15,'Historias de Usuario'!$O$6:$O$128,"Propuesta nueva") -> 0
B16: Total MVP (E1 a E10) | H16: =SUM(H6:H15) -> 34 | I16: =SUM(I6:I15) -> 122 | J16: =SUM(J6:J15) -> 82 | L16: =SUM(L6:L15) -> 19
B17: — | C17: Fuera del MVP | D17: Historias registradas para una versión posterior (prioridad Won't); no se estiman ni se modelan ahora. | E17: — | F17: — | G17: HU-35, HU-36 | H17: =COUNTIFS('Historias de Usuario'!$K$6:$K$128,$B17,'Historias de Usuario'!$O$6:$O$128,"<>Propuesta nueva") -> 2 | I17: — | J17: — | K17: — | L17: —
B20: Carga por responsable de desarrollo
B21: Responsable | D21: Puntos backlog MVP | E21: Puntos propuestas v2 | F21: Total con propuestas
B22: Bastián Ñiripil | D22: =SUMIFS('Historias de Usuario'!$M$6:$M$128,'Historias de Usuario'!$N$6:$N$128,$B22,'Historias de Usuario'!$O$6:$O$128,"<>Propuesta nueva") -> 71 | E22: =SUMIFS('Historias de Usuario'!$M$6:$M$128,'Historias de Usuario'!$N$6:$N$128,$B22,'Historias de Usuario'!$O$6:$O$128,"Propuesta nueva") -> 8 | F22: =D22+E22 -> 79
B23: Luis Pérez | D23: =SUMIFS('Historias de Usuario'!$M$6:$M$128,'Historias de Usuario'!$N$6:$N$128,$B23,'Historias de Usuario'!$O$6:$O$128,"<>Propuesta nueva") -> 51 | E23: =SUMIFS('Historias de Usuario'!$M$6:$M$128,'Historias de Usuario'!$N$6:$N$128,$B23,'Historias de Usuario'!$O$6:$O$128,"Propuesta nueva") -> 11 | F23: =D23+E23 -> 62
B24: Total | D24: =SUM(D22:D23) -> 122 | E24: =SUM(E22:E23) -> 19 | F24: =SUM(F22:F23) -> 141
B25: Las historias HU-19, HU-20 y HU-21 se reparten entre ambos responsables dentro de sus épicas.
B28: Objetivos de la Fase 1
B29: Código | C29: Objetivo
B30: OE1 | C30: Transacciones procesadas correctamente, error < 5 % en 100 registros
B31: OE2 | C31: ≥ 90 % de exactitud factual del agente IA en 25 consultas
B32: OE3 | C32: 100 % de alertas generadas correctamente en 100 casos simulados
B33: OE4 | C33: 100 % de requisitos no funcionales críticos (seguridad, acceso, Docker)
B34: OG | C34: Objetivo general: cubre la reportería, que no tiene un objetivo específico medible propio

Sheet Instructivo
B1: Historias de usuario y criterios de aceptación: Instructivo
B2: Proyecto CuidaTrack · Product Backlog v2 · 1 de octubre de 2026
B4: Columna | C4: Instrucciones
B5: Identificador (ID) de la historia | C5: Código que identifica unívocamente a la historia en el proyecto que se esté desarrollando. El formato debe ser elegido por el equipo. En CuidaTrack el formato es HU-NN (HU-01 a HU-41): correlativo único en todo el proyecto, que se mantiene aunque la historia cambie de épica o de prioridad.
B6: Rol | C6: Es el rol que está desempeñando el usuario cuando utiliza la funcionalidad que se está describiendo. Debe ser lo más especifico posible, describiendo el rol o actor que se está desempeñando. El enunciado puede escribirse como se sigue: Yo como un [Rol], desempeñando el rol de [Rol], como un [Rol], entre otros. Por ejemplo: Yo como cliente registrado. Desempeñando el rol de cliente registrado. Como un cliente registrado.
B7: Característica / Funcionalidad | C7: Representa la función que el rol quiere o necesita hacer en el sistema que se está desarrollando. Puede diferenciarse entre acciones obligatorias u opcionales, utilizando la palabra puede o necesita para describir la acción. Por ejemplo: Necesito realizar búsquedas de productos por categorías. Puedo seleccionar una categoría para ver el número de productos que tiene asociado.
B8: Razón / Resultado | C8: Lo que el rol necesita lograr al ejecutar la acción. Este es el resultado de ejecutar la acción desde el punto de vista del rol. Este punto puede ser opcional, pues la historia puede documentarse sólo con la definición del rol y la acción (sin definir la consecuencia).
B9: Número (#) de escenario | C9: Número (ejemplo 1, 2, 3 ó 4), que identifica al escenario asociado a la historia. En CuidaTrack cada historia tiene entre 1 y 4 escenarios; las historias fuera del MVP tienen un escenario "Por definir".
B10: Criterio de aceptación (título) | C10: Describe el contexto del escenario que define un comportamiento. Por ejemplo, si se toma el ejemplo de búsquedas de productos por categoría, un posible ejemplo pudiera ser: Categoría sin productos asociados.
B11: Contexto | C11: Proporciona mayor descripción sobre las condiciones que desencadenan el escenario.
B12: Evento | C12: Representa la acción que el usuario ejecuta, en el contexto definido para el escenario.
B13: Resultado / Comportamiento esperado | C13: Dado el contexto y la acción ejecutada por el usuario, la consecuencia es el comportamiento del sistema en esa situación.
B14: Épica | C14: Código de la épica a la que pertenece la historia (E1 a E10). El nombre, el propósito y los totales de cada épica están en la pestaña Épicas. Las historias fuera del MVP no tienen épica (—).
B15: Prioridad (MoSCoW) | C15: Must: sin esto no hay MVP. Should: importante, entra si hay capacidad. Could: deseable. Won't: fuera de esta versión. Se elige de una lista.
... B19: Criterios técnicos | C19: Detalles de implementación y metas de evaluación del equipo. La persona cuidadora no los ve, pero deben cumplirse para dar la historia por terminada. Aquí también se anotan las preguntas abiertas de cada historia.
B22: Convenciones del proyecto CuidaTrack
B23: Tema | C23: Convención
B24: Roles de usuario | C24: Cuidador/a principal: familiar que asume la mayor parte del cuidado en casa; crea la cuenta, registra a la persona mayor e invita al resto. Cuidador/a secundario/a: familiar que ayuda por turnos o en días puntuales; registra solo para la persona que le compartieron. Cuando una historia sirve a ambos, dice "cuidador/a". La persona mayor no usa la app.
B25: Enunciado de la historia | C25: Se escribe desde la persona cuidadora y en lenguaje cotidiano ("remedio", "hora médica"). La razón es siempre un resultado concreto para ella: tranquilidad, ahorro de tiempo, evitar errores, coordinarse con la familia o cuidarse a sí misma.
B26: Criterios de aceptación | C26: Describen lo que la persona cuidadora ve o hace, de forma verificable en una prueba con usuario. Los términos técnicos van solo en la columna Criterios técnicos.
B27: Comentarios en celdas | C27: Las celdas con comentario marcan cambios propuestos en la versión 2 que el equipo debe confirmar: puntos de HU-02, lista de HU-14, prioridad de HU-16 y responsable de HU-19.
B28: Preguntas abiertas | C28: Margen de la ventana horaria (HU-11). Versión de la escala de Zarit (HU-20). Quién otorga el consentimiento sobre los datos de la persona mayor (HU-03). Qué pasa con los cuidadores secundarios si el principal borra su cuenta (HU-04). A quién le llegan las alertas cuando el cuidado es compartido (HU-25). Cuánto dura la sesión abierta en el celular (HU-02). Si los avisos a la hora del remedio son factibles en la app web (HU-37).
B29: Pestaña Épicas | C29: Agrupa las historias por épica con su propósito, objetivos de la Fase 1 y responsable. Los conteos y puntos son fórmulas: se actualizan solos al editar las columnas Épica, Prioridad, Puntos, Responsable o Tipo / estado de la pestaña Historias de Usuario.
B30: Fuente | C30: Product Backlog v2 de CuidaTrack (1 de octubre de 2026), elaborado por Bastián Ñiripil y Luis Pérez.

Sheet Ejemplo
